<!-- models/roybot.xml : differential-drive robot, 2 wheels + caster -->
<mujoco model="roybot">
  <!-- implicitfast + wheel armature stabilize the low-inertia driven wheel DOF;
       plain Euler at dt=2ms makes the velocity-servo'd wheel explode. -->
  <option timestep="0.002" gravity="0 0 -9.81" integrator="implicitfast"/>
  <default>
    <joint damping="0.01" armature="0.001"/>
    <geom friction="1 0.1 0.01"/>
  </default>

  <worldbody>
    <geom name="floor" type="plane" size="5 5 0.1" rgba="0.85 0.9 0.85 1"
          friction="1 0.1 0.01"/>

    <body name="chassis" pos="0 0 0.03">
      <freejoint name="root"/>
      <geom name="chassis_geom" type="box" size="0.05 0.04 0.015" mass="0.30"
            rgba="0.3 0.45 0.8 1"/>
      <site name="imu" pos="0 0 0" size="0.005"/>

      <body name="left_wheel" pos="0 0.045 -0.005">
        <joint name="left_wheel_joint" type="hinge" axis="0 1 0"/>
        <geom type="cylinder" size="0.025 0.008" quat="0.7071 0.7071 0 0"
              mass="0.02" rgba="0.15 0.15 0.15 1" friction="1.2 0.1 0.01"/>
      </body>

      <body name="right_wheel" pos="0 -0.045 -0.005">
        <joint name="right_wheel_joint" type="hinge" axis="0 1 0"/>
        <geom type="cylinder" size="0.025 0.008" quat="0.7071 0.7071 0 0"
              mass="0.02" rgba="0.15 0.15 0.15 1" friction="1.2 0.1 0.01"/>
      </body>

      <!-- caster: low-friction ball so the rear slides freely -->
      <body name="caster" pos="0.04 0 -0.018">
        <geom type="sphere" size="0.012" mass="0.005" rgba="0.6 0.6 0.6 1"
              friction="0.05 0.005 0.0001"/>
      </body>
    </body>
  </worldbody>

  <actuator>
    <velocity name="left_motor"  joint="left_wheel_joint"  kv="5.0" forcerange="-1 1"/>
    <velocity name="right_motor" joint="right_wheel_joint" kv="5.0" forcerange="-1 1"/>
  </actuator>

  <sensor>
    <framepos    name="chassis_pos"    objtype="site" objname="imu"/>
    <framequat   name="chassis_quat"   objtype="site" objname="imu"/>
    <framelinvel name="chassis_linvel" objtype="site" objname="imu"/>
    <frameangvel name="chassis_angvel" objtype="site" objname="imu"/>
  </sensor>
</mujoco>
